Workbook
Name add: [1]Dropdownlist!$Y$2:$Y$3
Name ag: info!$H$2:$H$6
Name age_group: [2]datavalidation!$K$2:$K$7
Name Agegp: [1]Dropdownlist!$Q$2:$Q$7
Name bawlake: Location!$I$2:$I$10
Name Beneficiary: #REF!
Name cash_org: [3]Dropdownlist!$A$12:$A$20
Name CD_orgname: #REF!
Name CD_orgname: #REF!
Name CD_orgname: #REF!
Name CD_orgname: [4]Dropdownlist!$A$10:$A$12
Name Comments: #REF!
Name communityEH: #REF!
Name communityEH: #REF!
Name communityEH: #REF!
Name communityEH: [4]Dropdownlist!$A$123:$A$128
Name constructionfacilities: #REF!
Name covid: [5]Dropdown!$D$3:$D$6
Name covid: [6]Dropdown!$D$3:$D$6
Name CSO: [7]Info!$P$2:$P$22
Name Cut_off_score: #REF!
Name del: [1]Dropdownlist!$P$2:$P$5
Name Delivery: [5]Dropdown!$T$3:$T$6
Name Delivery: [6]Dropdown!$T$3:$T$6
Name demoso: Location!$I$11:$I$36
Name dsfsafa: #REF!
Name eawfa: #REF!
Name ECC: Table4[ECC]
Name EmOC: Data_validation!$R$2:$R$93
Name ess: Location!$B$16:$B$30
Name ethnicity: [2]datavalidation!$M$2:$M$8
Name ethnicity: [6]Dropdown!$G$3:$G$9
Name ethnicity: [6]Dropdown!$G$3:$G$9
Name ethnicity: Data_validation!$I$2:$I$15
Name event1: [7]list!$H$3:$H$6
Name EXIT: #REF!
Name Exit_reason: #REF!
Name Exit_reasons: #REF!
Name facility_type: Data_validation!$G$2:$G$3
Name familytype: #REF!
Name fb: [1]Dropdownlist!$X$2:$X$5
Name Formula_start: #REF!
Name fp_method: Data_validation!$N$2:$N$10
Name health_org: Data_validation!$C$2:$C$7
Name HH_type: #REF!
Name HH_type: #REF!
Name HH_type: #REF!
Name HH_type: [4]Dropdownlist!$A$15:$A$18
Name ho_tawng_ho_tao: Location!$I$141:$I$145
Name hopong: Location!$I$365:$I$386
Name hospital_type: [2]datavalidation!$O$2:$O$4
Name how: [2]datavalidation!$AK$2:$AK$11
Name how: [6]Dropdown!$V$2:$V$9
Name hpasawng: Location!$I$37:$I$44
Name hpruso: Location!$I$45:$I$58
Name hrp: [8]info!$P$2:$P$10
Name hrp: [8]info!$P$2:$P$10
Name hrp: [8]info!$P$2:$P$10
Name hrp: Data_validation!$K$2:$K$10
Name hsihseng: Location!$I$387:$I$399

Sheet info
A1: Township | B1: Village/Camp Name | C1: Type | F1: Tsp | H1: Age Group | K1: Subcat | M1: Subcat | N1: Disease's Category | P1: HighRiskPregnancy | R1: Matrix | T1: Nutrition | V1: Type of Disability | X1: Subcat | Y1: Disease's Category | Z1: Consultation Type | AA1: Consultation Type_revised
A2: Kyauktaw | B2: COC | C2: IDP | F2: Kyauktaw | H2: <10 yrs | I2: a | K2: Abdominal pain in pregnancy | M2: Pneumonia | N2: Pneumonia | P2: Short Stature | R2: Q12023 | T2: Normal | V2: Disability of seeing | X2: Abdominal pain in pregnancy | Y2: Obstetric problem | Z2: Reproductive Health | AA2: Reproductive Health
A3: Kyauktaw | B3: Man Kyaung | C3: IDP | F3: MraukU | H3: 10 - 19 yrs | I3: b | K3: Abscess | M3: Severe pneumonia | N3: Pneumonia | P3: Extreme age | R3: Q22023 | T3: -1SD | V3: Disability of hearing | X3: Abscess | Y3: Accident/minor sugical and injuries | Z3: Communicable disease | AA3: Communicable disease
A4: Kyauktaw | B4: Thar Ta Na Bate Man | C4: IDP | F4: Myebon | H4: 20 - 24 yrs | I4: c | K4: Acute cystitis | M4: Very severe pneumonia | N4: Pneumonia | P4: Teenage pregnancy | R4: Q32023 | T4: -2SD | V4: Disability of self care | X4: Accident/minor sugical and injuries | Y4: Accident/minor sugical and injuries | Z4: Injury related | AA4: Injury related
A5: Kyauktaw | B5: Kan Sauk Monestery | C5: IDP | H5: 25 - 49 yrs | I5: d | K5: Acute diarrhoea | M5: Upper Respiratory tract infection | N5: ARI/RTI | P5: Underlying Disease | R5: Q42023 | T5: -3SD | V5: Disability of walking | X5: Acute cystitis | Y5: Genito-urinary diseases | Z5: Non-communicable disease | AA5: Other
A6: Kyauktaw | B6: Thain Pyin Kyaung | C6: IDP | H6: 50 yrs + | I6: e | K6: Acute Pharyngitis | M6: Lower Respiratory tract infection | N6: ARI/RTI | P6: Grand Multipara | V6: Disability of communication | X6: Acute diarrhoea | Y6: Diarrhoea/ GE | Z6: Communicable disease | AA6: Communicable disease
A7: Kyauktaw | B7: Shan Ywar | C7: IDP | K7: Acute prostatitis | M7: Otitis | N7: ARI/RTI | P7: Previous LSCS Scar | V7: Disability with remembering | X7: Acute Pharyngitis | Y7: ARI/RTI | Z7: Communicable disease | AA7: Communicable disease
A8: Kyauktaw | B8: Thain Kyaung | C8: IDP | K8: Acute pyelonephritis | M8: Whooping cough (pertussis) | N8: ARI/RTI | P8: Twin Pregnancy | X8: Acute prostatitis | Y8: Genito-urinary diseases | Z8: Non-communicable disease | AA8: Non-communicable disease
A9: Kyauktaw | B9: Town Hall | C9: IDP | K9: Acute Severe asthma | M9: Bronchitis | N9: ARI/RTI | P9: Antepartum Hemorrhage | X9: Acute pyelonephritis | Y9: Genito-urinary diseases | Z9: Non-communicable disease | AA9: Non-communicable disease
A10: Kyauktaw | B10: Bu Dar | C10: IDP | F10: Extremely dissatisfied | H10: Recovered | K10: Acute sinusitis | M10: Bronchiolitis | N10: ARI/RTI | P10: Pre-eclampsia | X10: Acute Severe asthma | Y10: Asthma | Z10: Non-communicable disease | AA10: Non-communicable disease
A11: Kyauktaw | B11: Shwe Kyaung | C11: IDP | F11: Dissatisfied | H11: Improved but not recovered | K11: Acute upper airway obstruction | M11: Acute sinusitis | N11: ARI/RTI | X11: Acute sinusitis | Y11: ARI/RTI | Z11: Communicable disease | AA11: Communicable disease
A12: Kyauktaw | B12: Kan Gyee Shin | C12: IDP | F12: Partially satisfied | H12: Same condition | K12: Agitation | M12: Acute Pharyngitis | N12: ARI/RTI | X12: Acute upper airway obstruction | Y12: ARI/RTI | Z12: Communicable disease | AA12: Communicable disease
A13: Kyauktaw | B13: Nay Pu Khan | C13: IDP | F13: Satisfied | H13: Worse | K13: Allergic reaction | M13: Acute upper airway obstruction | N13: ARI/RTI | X13: Agitation | Y13: Mental disorders | Z13: mental health condition | AA13: mental health condition
A14: Kyauktaw | B14: Ka Wi Yadanar | C14: IDP | F14: Extremely Satisfied | H14: Ongoing/chronic problem | K14: Amenorrhoea | M14: Bronchitis | N14: ARI/RTI | X14: Allergic reaction | Y14: Skin infection/disease | Z14: Non-communicable disease | AA14: Non-communicable disease
A15: Kyauktaw | B15: Ma Har Mu Ni | C15: IDP | H15: Unsure | K15: Anaemia | M15: Bronchiolitis | N15: ARI/RTI | X15: Amenorrhoea | Y15: Gynecological problem | Z15: Reproductive Health | AA15: Reproductive Health
A16: Kyauktaw | B16: Nyaung Chaung | C16: IDP | K16: Animal/Insect bite | M16: Chest infection | N16: ARI/RTI | X16: Anaemia | Y16: Hematological disorder | Z16: Non-communicable disease | AA16: Non-communicable disease
A17: Kyauktaw | B17: Taung Min | C17: IDP | K17: Anxiety | M17: Common cold | N17: ARI/RTI | X17: Animal/Insect bite | Y17: Accident/minor sugical and injuries | Z17: Injury related | AA17: Injury related
A18: Kyauktaw | B18: War Taung | C18: IDP | F18: Very satisfied | H18: Yes, totally | K18: Arthalgia | M18: Flu with high fever | N18: ARI/RTI | X18: Anxiety | Y18: Mental disorders | Z18: mental health condition | AA18: mental health condition
A19: Kyauktaw | B19: Taung Pauk Monestery | C19: Rakhine Village | F19: Satisfied | H19: Yes, partially | K19: Asthma | M19: Respiratory viral infection | N19: ARI/RTI | X19: ARI/RTI | Y19: ARI/RTI | Z19: Communicable disease | AA19: Communicable disease
A20: Kyauktaw | B20: Hpa Yar Paung Monestery | C20: Rakhine Village | F20: Dissatisfied | H20: Not at all | K20: Back pain in pregnancy | M20: Tonsillar abscess | N20: ARI/RTI | X20: Arthalgia | Y20: Other (non-communicable) | Z20: Non-communicable disease | AA20: Non-communicable disease
A21: MraukU | B21: Pu Zun Hpe | C21: Rakhine Village | F21: Very dissatisfied | H21: Unsure | K21: Bacteria skin infection | M21: Tuberculosis | N21: ARI/RTI | X21: Asthma | Y21: Asthma | Z21: Non-communicable disease | AA21: Non-communicable disease
A22: MraukU | B22: Pi Pin Yin | C22: Rakhine Village | H22: Don’t know | K22: Bacterial vaginosis | M22: Pulmonary TB-suspect | N22: ARI/RTI | X22: Back pain in pregnancy | Y22: Obstetric problem | Z22: Reproductive Health | AA22: Reproductive Health
A23: MraukU | B23: Tein Nyo | C23: Rakhine Village | K23: Beri Beri | M23: Asthma | N23: Asthma | X23: Bacteria disease | Y23: Bacteria disease | Z23: Communicable disease | AA23: Communicable disease
A24: MraukU | B24: Tin Htein Kan | C24: Muslim Village | K24: Bleeding during pregnancy | M24: Acute Severe asthma | N24: Asthma | X24: Bacteria skin infection | Y24: Skin infection/disease | Z24: Communicable disease | AA24: Communicable disease
A25: MraukU | B25: Ywar Thit Kay | C25: Muslim Village | K25: Bronchiolitis | M25: Chronic Asthma | N25: Asthma | X25: Bacterial vaginosis | Y25: STI | Z25: Communicable disease | AA25: Communicable disease
A26: MraukU | B26: Pya Hla | K26: Bronchiolitis | M26: Dengue haemorrhagic fever | N26: DHF | X26: Beri Beri | Y26: Beri Beri | Z26: Non-communicable disease | AA26: Non-communicable disease
A27: MraukU | B27: Na Kan | K27: Bronchitis | M27: DHF suspect | N27: DHF | X27: Bleeding during pregnancy | Y27: Obstetric problem | Z27: Reproductive Health | AA27: Reproductive Health
A28: MraukU | B28: Ku Lar Chaung | K28: Bronchitis | M28: Dengue shock | N28: DHF | X28: Bronchiolitis | Y28: ARI/RTI | Z28: Communicable disease | AA28: Communicable disease
A29: MraukU | B29: Wet Hla | K29: Burns/wounds | M29: Acute diarrhoea | N29: Diarrhoea/ GE | X29: Bronchitis | Y29: ARI/RTI | Z29: Communicable disease | AA29: Communicable disease
A30: MraukU | B30: Taung Myint | K30: Cataract | M30: Severe dehydration with diarrhoea | N30: Diarrhoea/ GE | X30: Burns/wounds | Y30: Accident/minor sugical and injuries | Z30: Injury related | AA30: Injury related
A31: Myebon | B31: Kyee Gaung Taung | K31: Cerebral soft tissue infection | M31: Dehydration with diarrhoea | N31: Diarrhoea/ GE | X31: Cataract | Y31: Eye problem/disease | Z31: Non-communicable disease | AA31: Non-communicable disease
A32: Myebon | B32: Taung Gyi Yin | K32: Cervicitis | M32: Dysentery | N32: Dysentery | X32: Cerebral soft tissue infection | Y32: Meningitis and encephalitis | Z32: Communicable disease | AA32: Communicable disease
A33: Myebon | B33: Yae Shin | K33: Chest infection | M33: Beri Beri | N33: Beri Beri | X33: Cervicitis | Y33: Gynecological problem | Z33: Reproductive Health | AA33: Reproductive Health
A34: Myebon | B34: Ah Ngu Yaw Thit | K34: Chicken Pox | M34: Malnutrition | N34: Malnutrition | X34: Chest infection | Y34: ARI/RTI | Z34: Communicable disease | AA34: Communicable disease
A35: Myebon | B35: Yet Chaung | K35: Chlamydia | M35: Severe malnutrition | N35: Malnutrition | X35: Chicken Pox | Y35: Viral diseases | Z35: Communicable disease | AA35: Communicable disease
A36: Myebon | B36: Pya Thone | K36: Chronic Asthma | M36: Protein energy malnutrition | N36: Malnutrition | X36: Chlamydia | Y36: STI | Z36: Communicable disease | AA36: Communicable disease
A37: Myebon | B37: Pin Kat Taung Maw | K37: Colitis | M37: Stomatitis | N37: Malnutrition | X37: Chronic Asthma | Y37: Asthma | Z37: Non-communicable disease | AA37: Non-communicable disease
... A42: Myebon | B42: Taung Paw Camp | K42: Congenital heart disease | M42: DM | N42: Chronic medical disease | X42: Congenital abnormalities | Y42: Congenital abnormalities | Z42: Non-communicable disease | AA42: Non-communicable disease
K43: Congenital infection | M43: Hypertension | N43: Chronic medical disease | X43: Congenital abnormalities/deformities | Y43: Neonatal problem | Z43: Non-communicable disease | AA43: Non-communicable disease
K44: Conjunctivitis | M44: Heart disease | N44: Chronic medical disease | X44: Congenital deformaties | Y44: Congenital abnormalities | Z44: Non-communicable disease | AA44: Non-communicable disease
...

Sheet Def
A1: Sr No | B1: Item Name | C1: Operation Defination
A2: 1 | B2: New consultation | C2: 1.An individual who is seen for a first time at the Mobile Clinic 2.patient not previously seen in past 30 days (starting 1 January 2017) or seen for a new condition (confirm with patient record book) 3.For chronic cases, who is seen for first time at Mobile Clinic And/or acutely new attack or condition due to chronic background stage will be new case.
A3: 2 | B3: Follow up consultation | C3: Follow up consultation means to the same patient who present/ complaint with the same symptom(s) and/or come back to the clinic to re-check disease in the willingness of the patient or MD’s follow up appointment.
A4: 3 | B4: Age | C4: Age refers to completed age of the client (Year/month/day) If the client is under 1 month please describe completed days If the client is under 1 year please describe completed month
A5: 4 | B5: ANC 1 | C5: ANC-1 means antenatal care taken by pregant woman within first 12th to 14th weeks of gestation
A6: 5 | B6: ANC 2 | C6: ANC-2 means antenatal care taken by pregant woman within 15th to 28th week of gestation
A7: 6 | B7: ANC 3 | C7: ANC-3 means antenatal care taken by pregant woman within 29th to 34th week of gestation
A8: 7 | B8: ANC 4 | C8: ANC-4 means antenatal care taken by pregant woman after 34th week of gestation
A9: 8 | B9: TT 1 | C9: TT 1 means first dose of tetanus toxoid vaccine is given to the pregnant woman
A10: 9 | B10: TT 2 | C10: TT 2 means second dose of tetanus toxoid vaccine is given to the same pregnant woman
A11: 10 | B11: PNC 1 | C11: PNC-1 (within 48 hrs)
A12: 11 | B12: PNC 2 | C12: PNC-2 (After 48 hrs after Delivery)
A13: 14 | B13: new acceptor (Family planning) | C13: 1. woman who never used any modern FP method before 2. woman who change from one method to other method which wasn't used before 3. woman used some modern FP method previously and she used the same method again after 6 months later
... A16: 17 | B16: Moderate Acute Malnutrition | C16: 11.5 to 12.5 cm(MUAC) (Yellow)
B17: *Disease category is according to MSF guideline 2018 and the list is as follow
B18: Pneumonia | C18: Pneumonia
C19: Severe pneumonia
C20: Severe pneumonia
B21: ARI/RTI | C21: Upper Respiratory tract infection
C22: Lower Respiratory tract infection
C23: Otitis
C24: Whooping cough (pertussis)
C25: Bronchitis
C26: Bronchiolitis
C27: Acute sinusitis
C28: Acute pharyngitis
C29: Acute upper airway obstruction
C30: Bronchitis
C31: Bronchiolitis
C32: Chest infection
C33: Common cold
... C38: Pulmonary TB-suspect
B39: Asthma | C39: Asthma
C40: Acute Severe asthma
C41: Chronic Asthma
B42: DHF | C42: Dengue haemorrhagic fever
C43: DHF suspect
C44: Dengue shock
B45: Diarrhoea/ GE | C45: Acute Diarrhoea
C46: Severe dehydration with diarrhoea
...

Sheet PHC
A1: PHC Database
A2: Sr.No | B2: Fund | C2: Implementing Organization Name | D2: Health Post / Clinic | E2: State | F2: Township | G2: Village Tract | H2: Place | I2: Type of place (Camp/Village/Ward) | J2: Name of Medical Person | K2: Date of Consultation (mm/dd/yy) | L2: Register No. | M2: Register.Code | N2: New/ Follow up | O2: Name of patient | P2: Age_yr | Q2: Age_mth | R2: Age_day | S2: Age_Group | T2: Sex | U2: Address (if not the same with Moblile Clinic location) | V2: Father Name | W2: Diagnosis | X2: Sub_Category | Y2: Category | Z2: Consultation Type | AA2: Treatment | AB2: eligible to receive PEP? | AC2: Receive PEP within 72 hours | AD2: Disability | AE2: Refered or Not | AF2: Referral Date | AG2: Cause of referral | AH2: Name of Referred Place | AI2: Type of Referred Facility | AJ2: Follow-up Date | AK2: Teleconsultation | AL2: Remarks | AM2: referral | AN2: PEP
A3: 1 | B3: BHA | C3: Shining Star | D3: Mobile Clinic | E3: Mandalay | F3: Amarapura | H3: Myit Too | I3: Village | K3: 46037 | L3: 1 | M3: =IF(phc_8[[#This Row],[Register No.]]="","",C3&"-"&D3&"-"&"BHA-PHC-"&phc_8[[#This Row],[Register No.]]) -> Shining Star-Mobile Clinic-BHA-PHC-1 | N3: New | O3: Daw Khin Hla | P3: 80 | S3: =IF(AND(ISBLANK(P3),ISBLANK(Q3),ISBLANK(R3))," ", IF(OR(P3<5,AND(P3=" ",Q3<>" ",R3<>" ")),"<5 yrs", IF(AND(P3>=5,P3<=14),"5 - 14 yrs", IF(AND(P3>=15,P3<=18),"15 - 18 yrs", IF(AND(P3>=19,P3<=49),"19 - 49 yrs","50 yrs +"))))) -> 50 yrs + | T3: Female | U3: Myit Too | V3: U Kyu | W3: HT | X3: Hypertension | Y3: =INDEX(info!$Y$2:$Y$192,MATCH(phc_8[[#This Row],[Sub_Category]],info!$X$2:$X$192,0)) -> Chronic medical disease | Z3: {=INDEX(info!$AA$2:$AA$192,MATCH(PHC!$X3&PHC!$Y3,info!$X$2:$X$192&info!$Y$2:$Y$192,0))} -> Non-communicable disease | AA3: Amlo5, MV, Betex | AB3: No | AC3: No | AD3: No | AE3: No | AK3: No | AM3: =IF(AF3="","","Q"&INT((MONTH(AF3)-1)/3)+1&YEAR(AF3)&#REF!&T3) | AN3: =IF(K3="","","Q"&INT((MONTH(K3)-1)/3)+1&YEAR(K3)&#REF!) -> #REF!
A4: 2 | B4: BHA | C4: Shining Star | D4: Mobile Clinic | E4: Mandalay | F4: Amarapura | H4: Myit Too | I4: Village | K4: 46037 | L4: 2 | M4: =IF(phc_8[[#This Row],[Register No.]]="","",C4&"-"&D4&"-"&"BHA-PHC-"&phc_8[[#This Row],[Register No.]]) -> Shining Star-Mobile Clinic-BHA-PHC-2 | N4: New | O4: Daw Khin Yee | P4: 89 | S4: =IF(AND(ISBLANK(P4),ISBLANK(Q4),ISBLANK(R4))," ", IF(OR(P4<5,AND(P4=" ",Q4<>" ",R4<>" ")),"<5 yrs", IF(AND(P4>=5,P4<=14),"5 - 14 yrs", IF(AND(P4>=15,P4<=18),"15 - 18 yrs", IF(AND(P4>=19,P4<=49),"19 - 49 yrs","50 yrs +"))))) -> 50 yrs + | T4: Female | U4: Myit Too | V4: U Thi Hla | W4: HT | X4: Hypertension | Y4: =INDEX(info!$Y$2:$Y$192,MATCH(phc_8[[#This Row],[Sub_Category]],info!$X$2:$X$192,0)) -> Chronic medical disease | Z4: {=INDEX(info!$AA$2:$AA$192,MATCH(PHC!$X4&PHC!$Y4,info!$X$2:$X$192&info!$Y$2:$Y$192,0))} -> Non-communicable disease | AA4: IV25%+VitC, Amlo5, Para, MV, VitC | AB4: No | AC4: No | AD4: No | AE4: No | AK4: No | AM4: =IF(AF4="","","Q"&INT((MONTH(AF4)-1)/3)+1&YEAR(AF4)&#REF!&T4) | AN4: =IF(K4="","","Q"&INT((MONTH(K4)-1)/3)+1&YEAR(K4)&#REF!) -> #REF!
A5: 3 | B5: BHA | C5: Shining Star | D5: Mobile Clinic | E5: Mandalay | F5: Amarapura | H5: Myit Too | I5: Village | K5: 46037 | L5: 3 | M5: =IF(phc_8[[#This Row],[Register No.]]="","",C5&"-"&D5&"-"&"BHA-PHC-"&phc_8[[#This Row],[Register No.]]) -> Shining Star-Mobile Clinic-BHA-PHC-3 | N5: New | O5: Daw Mya Aye | P5: 63 | S5: =IF(AND(ISBLANK(P5),ISBLANK(Q5),ISBLANK(R5))," ", IF(OR(P5<5,AND(P5=" ",Q5<>" ",R5<>" ")),"<5 yrs", IF(AND(P5>=5,P5<=14),"5 - 14 yrs", IF(AND(P5>=15,P5<=18),"15 - 18 yrs", IF(AND(P5>=19,P5<=49),"19 - 49 yrs","50 yrs +"))))) -> 50 yrs + | T5: Female | U5: Myit Too | V5: U Kho | W5: Skin Allergy | X5: Weakness | Y5: =INDEX(info!$Y$2:$Y$192,MATCH(phc_8[[#This Row],[Sub_Category]],info!$X$2:$X$192,0)) -> Other (non-communicable) | Z5: {=INDEX(info!$AA$2:$AA$192,MATCH(PHC!$X5&PHC!$Y5,info!$X$2:$X$192&info!$Y$2:$Y$192,0))} -> Other | AA5: IV B'ton, B'ton, Ranitadine, Ibu, Caladyl Lotion | AB5: No | AC5: No | AD5: No | AE5: No | AK5: No | AM5: =IF(AF5="","","Q"&INT((MONTH(AF5)-1)/3)+1&YEAR(AF5)&#REF!&T5) | AN5: =IF(K5="","","Q"&INT((MONTH(K5)-1)/3)+1&YEAR(K5)&#REF!) -> #REF!
A6: 4 | B6: BHA | C6: Shining Star | D6: Mobile Clinic | E6: Mandalay | F6: Amarapura | H6: Myit Too | I6: Village | K6: 46037 | L6: 4 | M6: =IF(phc_8[[#This Row],[Register No.]]="","",C6&"-"&D6&"-"&"BHA-PHC-"&phc_8[[#This Row],[Register No.]]) -> Shining Star-Mobile Clinic-BHA-PHC-4 | N6: New | O6: Daw Nu Nu Yee | P6: 73 | S6: =IF(AND(ISBLANK(P6),ISBLANK(Q6),ISBLANK(R6))," ", IF(OR(P6<5,AND(P6=" ",Q6<>" ",R6<>" ")),"<5 yrs", IF(AND(P6>=5,P6<=14),"5 - 14 yrs", IF(AND(P6>=15,P6<=18),"15 - 18 yrs", IF(AND(P6>=19,P6<=49),"19 - 49 yrs","50 yrs +"))))) -> 50 yrs + | T6: Female | U6: Myit Too | V6: U Kan Oo | W6: Muscle Pain | X6: Muscle Pain | Y6: =INDEX(info!$Y$2:$Y$192,MATCH(phc_8[[#This Row],[Sub_Category]],info!$X$2:$X$192,0)) -> Other (non-communicable) | Z6: {=INDEX(info!$AA$2:$AA$192,MATCH(PHC!$X6&PHC!$Y6,info!$X$2:$X$192&info!$Y$2:$Y$192,0))} -> Other | AA6: IV B12, Gabapentin, Betex, Ca+ | AB6: No | AC6: No | AD6: No | AE6: No | AK6: No | AM6: =IF(AF6="","","Q"&INT((MONTH(AF6)-1)/3)+1&YEAR(AF6)&#REF!&T6) | AN6: =IF(K6="","","Q"&INT((MONTH(K6)-1)/3)+1&YEAR(K6)&#REF!) -> #REF!
A7: 5 | B7: BHA | C7: Shining Star | D7: Mobile Clinic | E7: Mandalay | F7: Amarapura | H7: Myit Too | I7: Village | K7: 46037 | L7: 5 | M7: =IF(phc_8[[#This Row],[Register No.]]="","",C7&"-"&D7&"-"&"BHA-PHC-"&phc_8[[#This Row],[Register No.]]) -> Shining Star-Mobile Clinic-BHA-PHC-5 | N7: New | O7: Daw Kyu Kyu San | P7: 50 | S7: =IF(AND(ISBLANK(P7),ISBLANK(Q7),ISBLANK(R7))," ", IF(OR(P7<5,AND(P7=" ",Q7<>" ",R7<>" ")),"<5 yrs", IF(AND(P7>=5,P7<=14),"5 - 14 yrs", IF(AND(P7>=15,P7<=18),"15 - 18 yrs", IF(AND(P7>=19,P7<=49),"19 - 49 yrs","50 yrs +"))))) -> 50 yrs + | T7: Female | U7: Myit Too | V7: U Kyi | W7: HT | X7: Hypertension | Y7: =INDEX(info!$Y$2:$Y$192,MATCH(phc_8[[#This Row],[Sub_Category]],info!$X$2:$X$192,0)) -> Chronic medical disease | Z7: {=INDEX(info!$AA$2:$AA$192,MATCH(PHC!$X7&PHC!$Y7,info!$X$2:$X$192&info!$Y$2:$Y$192,0))} -> Non-communicable disease | AA7: IV Pantocid, Amlo5, Pantocid, Zinc, Air X | AB7: No | AC7: No | AD7: No | AE7: No | AK7: No | AM7: =IF(AF7="","","Q"&INT((MONTH(AF7)-1)/3)+1&YEAR(AF7)&#REF!&T7) | AN7: =IF(K7="","","Q"&INT((MONTH(K7)-1)/3)+1&YEAR(K7)&#REF!) -> #REF!
A8: 6 | B8: BHA | C8: Shining Star | D8: Mobile Clinic | E8: Mandalay | F8: Amarapura | H8: Myit Too | I8: Village | K8: 46037 | L8: 6 | M8: =IF(phc_8[[#This Row],[Register No.]]="","",C8&"-"&D8&"-"&"BHA-PHC-"&phc_8[[#This Row],[Register No.]]) -> Shining Star-Mobile Clinic-BHA-PHC-6 | N8: New | O8: Daw Aye Yee | P8: 78 | S8: =IF(AND(ISBLANK(P8),ISBLANK(Q8),ISBLANK(R8))," ", IF(OR(P8<5,AND(P8=" ",Q8<>" ",R8<>" ")),"<5 yrs", IF(AND(P8>=5,P8<=14),"5 - 14 yrs", IF(AND(P8>=15,P8<=18),"15 - 18 yrs", IF(AND(P8>=19,P8<=49),"19 - 49 yrs","50 yrs +"))))) -> 50 yrs + | T8: Female | U8: Myit Too | V8: U Kan Oo | W8: Muscle Pain | X8: Muscle Pain | Y8: =INDEX(info!$Y$2:$Y$192,MATCH(phc_8[[#This Row],[Sub_Category]],info!$X$2:$X$192,0)) -> Other (non-communicable) | Z8: {=INDEX(info!$AA$2:$AA$192,MATCH(PHC!$X8&PHC!$Y8,info!$X$2:$X$192&info!$Y$2:$Y$192,0))} -> Other | AA8: IV B12, Para, Ca+, MV | AB8: No | AC8: No | AD8: No | AE8: No | AK8: No | AM8: =IF(AF8="","","Q"&INT((MONTH(AF8)-1)/3)+1&YEAR(AF8)&#REF!&T8) | AN8: =IF(K8="","","Q"&INT((MONTH(K8)-1)/3)+1&YEAR(K8)&#REF!) -> #REF!
A9: 7 | B9: BHA | C9: Shining Star | D9: Mobile Clinic | E9: Mandalay | F9: Amarapura | H9: Myit Too | I9: Village | K9: 46037 | L9: 7 | M9: =IF(phc_8[[#This Row],[Register No.]]="","",C9&"-"&D9&"-"&"BHA-PHC-"&phc_8[[#This Row],[Register No.]]) -> Shining Star-Mobile Clinic-BHA-PHC-7 | N9: New | O9: Daw Moh Moh Thwin | P9: 49 | S9: =IF(AND(ISBLANK(P9),ISBLANK(Q9),ISBLANK(R9))," ", IF(OR(P9<5,AND(P9=" ",Q9<>" ",R9<>" ")),"<5 yrs", IF(AND(P9>=5,P9<=14),"5 - 14 yrs", IF(AND(P9>=15,P9<=18),"15 - 18 yrs", IF(AND(P9>=19,P9<=49),"19 - 49 yrs","50 yrs +"))))) -> 19 - 49 yrs | T9: Female | U9: Myit Too | V9: U Thaung Han | W9: Flu | X9: Flu with high fever | Y9: =INDEX(info!$Y$2:$Y$192,MATCH(phc_8[[#This Row],[Sub_Category]],info!$X$2:$X$192,0)) -> ARI/RTI | Z9: {=INDEX(info!$AA$2:$AA$192,MATCH(PHC!$X9&PHC!$Y9,info!$X$2:$X$192&info!$Y$2:$Y$192,0))} -> Communicable disease | AA9: Amlo5, Para, Cefixime, VitC, Betex | AB9: No | AC9: No | AD9: No | AE9: No | AK9: No | AM9: =IF(AF9="","","Q"&INT((MONTH(AF9)-1)/3)+1&YEAR(AF9)&#REF!&T9) | AN9: =IF(K9="","","Q"&INT((MONTH(K9)-1)/3)+1&YEAR(K9)&#REF!) -> #REF!
A10: 8 | B10: BHA | C10: Shining Star | D10: Mobile Clinic | E10: Mandalay | F10: Amarapura | H10: Myit Too | I10: Village | K10: 46037 | L10: 8 | M10: =IF(phc_8[[#This Row],[Register No.]]="","",C10&"-"&D10&"-"&"BHA-PHC-"&phc_8[[#This Row],[Register No.]]) -> Shining Star-Mobile Clinic-BHA-PHC-8 | N10: New | O10: Mg Han Min Khant | S10: =IF(AND(ISBLANK(P10),ISBLANK(Q10),ISBLANK(R10))," ", IF(OR(P10<5,AND(P10=" ",Q10<>" ",R10<>" ")),"<5 yrs", IF(AND(P10>=5,P10<=14),"5 - 14 yrs", IF(AND(P10>=15,P10<=18),"15 - 18 yrs", IF(AND(P10>=19,P10<=49),"19 - 49 yrs","50 yrs +"))))) | T10: Male | U10: Myit Too | V10: U Nay Khant | W10: CP | X10: Congenital abnormalities | Y10: =INDEX(info!$Y$2:$Y$192,MATCH(phc_8[[#This Row],[Sub_Category]],info!$X$2:$X$192,0)) -> Congenital abnormalities | Z10: {=INDEX(info!$AA$2:$AA$192,MATCH(PHC!$X10&PHC!$Y10,info!$X$2:$X$192&info!$Y$2:$Y$192,0))} -> Non-communicable disease | AA10: PB Vita | AB10: No | AC10: No | AD10: No | AE10: No | AK10: No | AM10: =IF(AF10="","","Q"&INT((MONTH(AF10)-1)/3)+1&YEAR(AF10)&#REF!&T10) | AN10: =IF(K10="","","Q"&INT((MONTH(K10)-1)/3)+1&YEAR(K10)&#REF!) -> #REF!
A11: 9 | B11: BHA | C11: Shining Star | D11: Mobile Clinic | E11: Mandalay | F11: Amarapura | H11: Myit Too | I11: Village | K11: 46037 | L11: 9 | M11: =IF(phc_8[[#This Row],[Register No.]]="","",C11&"-"&D11&"-"&"BHA-PHC-"&phc_8[[#This Row],[Register No.]]) -> Shining Star-Mobile Clinic-BHA-PHC-9 | N11: New | O11: U Nyay | P11: 51 | S11: =IF(AND(ISBLANK(P11),ISBLANK(Q11),ISBLANK(R11))," ", IF(OR(P11<5,AND(P11=" ",Q11<>" ",R11<>" ")),"<5 yrs", IF(AND(P11>=5,P11<=14),"5 - 14 yrs", IF(AND(P11>=15,P11<=18),"15 - 18 yrs", IF(AND(P11>=19,P11<=49),"19 - 49 yrs","50 yrs +"))))) -> 50 yrs + | T11: Male | U11: Myit Too | V11: U Aung Kyaw | W11: HT/DM | X11: Hypertension | Y11: =INDEX(info!$Y$2:$Y$192,MATCH(phc_8[[#This Row],[Sub_Category]],info!$X$2:$X$192,0)) -> Chronic medical disease | Z11: {=INDEX(info!$AA$2:$AA$192,MATCH(PHC!$X11&PHC!$Y11,info!$X$2:$X$192&info!$Y$2:$Y$192,0))} -> Non-communicable disease | AA11: Amlo5, MV, Cifram Eye Drop | AB11: No | AC11: No | AD11: No | AE11: No | AK11: No | AM11: =IF(AF11="","","Q"&INT((MONTH(AF11)-1)/3)+1&YEAR(AF11)&#REF!&T11) | AN11: =IF(K11="","","Q"&INT((MONTH(K11)-1)/3)+1&YEAR(K11)&#REF!) -> #REF!
A12: 10 | B12: BHA | C12: Shining Star | D12: Mobile Clinic | E12: Mandalay | F12: Amarapura | H12: Myit Too | I12: Village | K12: 46037 | L12: 10 | M12: =IF(phc_8[[#This Row],[Register No.]]="","",C12&"-"&D12&"-"&"BHA-PHC-"&phc_8[[#This Row],[Register No.]]) -> Shining Star-Mobile Clinic-BHA-PHC-10 | N12: New | O12: Daw San San Myint | P12: 65 | S12: =IF(AND(ISBLANK(P12),ISBLANK(Q12),ISBLANK(R12))," ", IF(OR(P12<5,AND(P12=" ",Q12<>" ",R12<>" ")),"<5 yrs", IF(AND(P12>=5,P12<=14),"5 - 14 yrs", IF(AND(P12>=15,P12<=18),"15 - 18 yrs", IF(AND(P12>=19,P12<=49),"19 - 49 yrs","50 yrs +"))))) -> 50 yrs + | T12: Female | U12: Myit Too | V12: U Tin Aung | W12: HT | X12: Hypertension | Y12: =INDEX(info!$Y$2:$Y$192,MATCH(phc_8[[#This Row],[Sub_Category]],info!$X$2:$X$192,0)) -> Chronic medical disease | Z12: {=INDEX(info!$AA$2:$AA$192,MATCH(PHC!$X12&PHC!$Y12,info!$X$2:$X$192&info!$Y$2:$Y$192,0))} -> Non-communicable disease | AA12: IV Hydrocortisone, Dextro, Salbutamol, Gabapentin, Nifedapine | AB12: No | AC12: No | AD12: No | AE12: No | AK12: No | AM12: =IF(AF12="","","Q"&INT((MONTH(AF12)-1)/3)+1&YEAR(AF12)&#REF!&T12) | AN12: =IF(K12="","","Q"&INT((MONTH(K12)-1)/3)+1&YEAR(K12)&#REF!) -> #REF!
A13: 11 | B13: BHA | C13: Shining Star | D13: Mobile Clinic | E13: Mandalay | F13: Amarapura | H13: Myit Too | I13: Village | K13: 46037 | L13: 11 | M13: =IF(phc_8[[#This Row],[Register No.]]="","",C13&"-"&D13&"-"&"BHA-PHC-"&phc_8[[#This Row],[Register No.]]) -> Shining Star-Mobile Clinic-BHA-PHC-11 | N13: New | O13: Daw Tin Hla | P13: 78 | S13: =IF(AND(ISBLANK(P13),ISBLANK(Q13),ISBLANK(R13))," ", IF(OR(P13<5,AND(P13=" ",Q13<>" ",R13<>" ")),"<5 yrs", IF(AND(P13>=5,P13<=14),"5 - 14 yrs", IF(AND(P13>=15,P13<=18),"15 - 18 yrs", IF(AND(P13>=19,P13<=49),"19 - 49 yrs","50 yrs +"))))) -> 50 yrs + | T13: Female | U13: Myit Too | V13: U Hla Mg | W13: HT | X13: Hypertension | Y13: =INDEX(info!$Y$2:$Y$192,MATCH(phc_8[[#This Row],[Sub_Category]],info!$X$2:$X$192,0)) -> Chronic medical disease | Z13: {=INDEX(info!$AA$2:$AA$192,MATCH(PHC!$X13&PHC!$Y13,info!$X$2:$X$192&info!$Y$2:$Y$192,0))} -> Non-communicable disease | AA13: Amlo5,Para,MV, Ca+ | AB13: No | AC13: No | AD13: No | AE13: No | AK13: No | AM13: =IF(AF13="","","Q"&INT((MONTH(AF13)-1)/3)+1&YEAR(AF13)&#REF!&T13) | AN13: =IF(K13="","","Q"&INT((MONTH(K13)-1)/3)+1&YEAR(K13)&#REF!) -> #REF!
A14: 12 | B14: BHA | C14: Shining Star | D14: Mobile Clinic | E14: Mandalay | F14: Amarapura | H14: Myit Too | I14: Village | K14: 46037 | L14: 12 | M14: =IF(phc_8[[#This Row],[Register No.]]="","",C14&"-"&D14&"-"&"BHA-PHC-"&phc_8[[#This Row],[Register No.]]) -> Shining Star-Mobile Clinic-BHA-PHC-12 | N14: New | O14: Daw Kyi Htay | P14: 73 | S14: =IF(AND(ISBLANK(P14),ISBLANK(Q14),ISBLANK(R14))," ", IF(OR(P14<5,AND(P14=" ",Q14<>" ",R14<>" ")),"<5 yrs", IF(AND(P14>=5,P14<=14),"5 - 14 yrs", IF(AND(P14>=15,P14<=18),"15 - 18 yrs", IF(AND(P14>=19,P14<=49),"19 - 49 yrs","50 yrs +"))))) -> 50 yrs + | T14: Female | U14: Myit Too | V14: U Hla Mg | W14: Asthma | X14: Asthma | Y14: =INDEX(info!$Y$2:$Y$192,MATCH(phc_8[[#This Row],[Sub_Category]],info!$X$2:$X$192,0)) -> Asthma | Z14: {=INDEX(info!$AA$2:$AA$192,MATCH(PHC!$X14&PHC!$Y14,info!$X$2:$X$192&info!$Y$2:$Y$192,0))} -> Non-communicable disease | AA14: IV Hydrocortisone, Dextro, Prednisolone, MV, Cefixime | AB14: No | AC14: No | AD14: No | AE14: No | AK14: No | AM14: =IF(AF14="","","Q"&INT((MONTH(AF14)-1)/3)+1&YEAR(AF14)&#REF!&T14) | AN14: =IF(K14="","","Q"&INT((MONTH(K14)-1)/3)+1&YEAR(K14)&#REF!) -> #REF!
A15: 13 | B15: BHA | C15: Shining Star | D15: Mobile Clinic | E15: Mandalay | F15: Amarapura | H15: Myit Too | I15: Village | K15: 46037 | L15: 13 | M15: =IF(phc_8[[#This Row],[Register No.]]="","",C15&"-"&D15&"-"&"BHA-PHC-"&phc_8[[#This Row],[Register No.]]) -> Shining Star-Mobile Clinic-BHA-PHC-13 | N15: New | O15: Daw Mya Win | P15: 68 | S15: =IF(AND(ISBLANK(P15),ISBLANK(Q15),ISBLANK(R15))," ", IF(OR(P15<5,AND(P15=" ",Q15<>" ",R15<>" ")),"<5 yrs", IF(AND(P15>=5,P15<=14),"5 - 14 yrs", IF(AND(P15>=15,P15<=18),"15 - 18 yrs", IF(AND(P15>=19,P15<=49),"19 - 49 yrs","50 yrs +"))))) -> 50 yrs + | T15: Female | U15: Myit Too | V15: U Than Kyaw | W15: DM | X15: DM | Y15: =INDEX(info!$Y$2:$Y$192,MATCH(phc_8[[#This Row],[Sub_Category]],info!$X$2:$X$192,0)) -> Chronic medical disease | Z15: {=INDEX(info!$AA$2:$AA$192,MATCH(PHC!$X15&PHC!$Y15,info!$X$2:$X$192&info!$Y$2:$Y$192,0))} -> Non-communicable disease | AA15: Metformin, Zinc, Betex | AB15: No | AC15: No | AD15: No | AE15: No | AK15: No | AM15: =IF(AF15="","","Q"&INT((MONTH(AF15)-1)/3)+1&YEAR(AF15)&#REF!&T15) | AN15: =IF(K15="","","Q"&INT((MONTH(K15)-1)/3)+1&YEAR(K15)&#REF!) -> #REF!
A16: 14 | B16: BHA | C16: Shining Star | D16: Mobile Clinic | E16: Mandalay | F16: Amarapura | H16: Myit Too | I16: Village | K16: 46037 | L16: 14 | M16: =IF(phc_8[[#This Row],[Register No.]]="","",C16&"-"&D16&"-"&"BHA-PHC-"&phc_8[[#This Row],[Register No.]]) -> Shining Star-Mobile Clinic-BHA-PHC-14 | N16: New | O16: Daw Yin Myint | P16: 80 | S16: =IF(AND(ISBLANK(P16),ISBLANK(Q16),ISBLANK(R16))," ", IF(OR(P16<5,AND(P16=" ",Q16<>" ",R16<>" ")),"<5 yrs", IF(AND(P16>=5,P16<=14),"5 - 14 yrs", IF(AND(P16>=15,P16<=18),"15 - 18 yrs", IF(AND(P16>=19,P16<=49),"19 - 49 yrs","50 yrs +"))))) -> 50 yrs + | T16: Female | U16: Myit Too | V16: U Chit | W16: HT | X16: Hypertension | Y16: =INDEX(info!$Y$2:$Y$192,MATCH(phc_8[[#This Row],[Sub_Category]],info!$X$2:$X$192,0)) -> Chronic medical disease | Z16: {=INDEX(info!$AA$2:$AA$192,MATCH(PHC!$X16&PHC!$Y16,info!$X$2:$X$192&info!$Y$2:$Y$192,0))} -> Non-communicable disease | AA16: Amlo10, Metformin, DMR30, Para, Betex | AB16: No | AC16: No | AD16: No | AE16: No | AK16: No | AM16: =IF(AF16="","","Q"&INT((MONTH(AF16)-1)/3)+1&YEAR(AF16)&#REF!&T16) | AN16: =IF(K16="","","Q"&INT((MONTH(K16)-1)/3)+1&YEAR(K16)&#REF!) -> #REF!
A17: 15 | B17: BHA | C17: Shining Star | D17: Mobile Clinic | E17: Mandalay | F17: Amarapura | H17: Myit Too | I17: Village | K17: 46037 | L17: 15 | M17: =IF(phc_8[[#This Row],[Register No.]]="","",C17&"-"&D17&"-"&"BHA-PHC-"&phc_8[[#This Row],[Register No.]]) -> Shining Star-Mobile Clinic-BHA-PHC-15 | N17: New | O17: U Kyaw Linn Soe | P17: 45 | S17: =IF(AND(ISBLANK(P17),ISBLANK(Q17),ISBLANK(R17))," ", IF(OR(P17<5,AND(P17=" ",Q17<>" ",R17<>" ")),"<5 yrs", IF(AND(P17>=5,P17<=14),"5 - 14 yrs", IF(AND(P17>=15,P17<=18),"15 - 18 yrs", IF(AND(P17>=19,P17<=49),"19 - 49 yrs","50 yrs +"))))) -> 19 - 49 yrs | T17: Male | U17: Myit Too | V17: U Nyein | W17: Injuries | X17: Injuries | Y17: =INDEX(info!$Y$2:$Y$192,MATCH(phc_8[[#This Row],[Sub_Category]],info!$X$2:$X$192,0)) -> Accident/minor sugical and injuries | Z17: {=INDEX(info!$AA$2:$AA$192,MATCH(PHC!$X17&PHC!$Y17,info!$X$2:$X$192&info!$Y$2:$Y$192,0))} -> Injury related | AA17: IM Diclo, Ibu, Omex, Ca+ | AB17: No | AC17: No | AD17: No | AE17: No | AK17: No | AM17: =IF(AF17="","","Q"&INT((MONTH(AF17)-1)/3)+1&YEAR(AF17)&#REF!&T17) | AN17: =IF(K17="","","Q"&INT((MONTH(K17)-1)/3)+1&YEAR(K17)&#REF!) -> #REF!
A18: 16 | B18: BHA | C18: Shining Star | D18: Mobile Clinic | E18: Mandalay | F18: Amarapura | H18: Myit Too | I18: Village | K18: 46037 | L18: 16 | M18: =IF(phc_8[[#This Row],[Register No.]]="","",C18&"-"&D18&"-"&"BHA-PHC-"&phc_8[[#This Row],[Register No.]]) -> Shining Star-Mobile Clinic-BHA-PHC-16 | N18: New | O18: Daw Shwe Myint | P18: 65 | S18: =IF(AND(ISBLANK(P18),ISBLANK(Q18),ISBLANK(R18))," ", IF(OR(P18<5,AND(P18=" ",Q18<>" ",R18<>" ")),"<5 yrs", IF(AND(P18>=5,P18<=14),"5 - 14 yrs", IF(AND(P18>=15,P18<=18),"15 - 18 yrs", IF(AND(P18>=19,P18<=49),"19 - 49 yrs","50 yrs +"))))) -> 50 yrs + | T18: Female | U18: Myit Too | V18: U Nyein | W18: HT | X18: Hypertension | Y18: =INDEX(info!$Y$2:$Y$192,MATCH(phc_8[[#This Row],[Sub_Category]],info!$X$2:$X$192,0)) -> Chronic medical disease | Z18: {=INDEX(info!$AA$2:$AA$192,MATCH(PHC!$X18&PHC!$Y18,info!$X$2:$X$192&info!$Y$2:$Y$192,0))} -> Non-communicable disease | AA18: Amlo5, MV, Zinc | AB18: No | AC18: No | AD18: No | AE18: No | AK18: No | AM18: =IF(AF18="","","Q"&INT((MONTH(AF18)-1)/3)+1&YEAR(AF18)&#REF!&T18) | AN18: =IF(K18="","","Q"&INT((MONTH(K18)-1)/3)+1&YEAR(K18)&#REF!) -> #REF!
A19: 17 | B19: BHA | C19: Shining Star | D19: Mobile Clinic | E19: Mandalay | F19: Amarapura | H19: Myit Too | I19: Village | K19: 46037 | L19: 17 | M19: =IF(phc_8[[#This Row],[Register No.]]="","",C19&"-"&D19&"-"&"BHA-PHC-"&phc_8[[#This Row],[Register No.]]) -> Shining Star-Mobile Clinic-BHA-PHC-17 | N19: New | O19: U Nyi | P19: 65 | S19: =IF(AND(ISBLANK(P19),ISBLANK(Q19),ISBLANK(R19))," ", IF(OR(P19<5,AND(P19=" ",Q19<>" ",R19<>" ")),"<5 yrs", IF(AND(P19>=5,P19<=14),"5 - 14 yrs", IF(AND(P19>=15,P19<=18),"15 - 18 yrs", IF(AND(P19>=19,P19<=49),"19 - 49 yrs","50 yrs +"))))) -> 50 yrs + | T19: Male | U19: Myit Too | V19: U Hla Sein | W19: Back Pain | X19: Muscle Pain | Y19: =INDEX(info!$Y$2:$Y$192,MATCH(phc_8[[#This Row],[Sub_Category]],info!$X$2:$X$192,0)) -> Other (non-communicable) | Z19: {=INDEX(info!$AA$2:$AA$192,MATCH(PHC!$X19&PHC!$Y19,info!$X$2:$X$192&info!$Y$2:$Y$192,0))} -> Other | AA19: IV B12, Ibu, Omex, Ca+, Gabapentin | AB19: No | AC19: No | AD19: No | AE19: No | AK19: No | AM19: =IF(AF19="","","Q"&INT((MONTH(AF19)-1)/3)+1&YEAR(AF19)&#REF!&T19) | AN19: =IF(K19="","","Q"&INT((MONTH(K19)-1)/3)+1&YEAR(K19)&#REF!) -> #REF!
A20: 18 | B20: BHA | C20: Shining Star | D20: Mobile Clinic | E20: Mandalay | F20: Amarapura | H20: Myit Too | I20: Village | K20: 46037 | L20: 18 | M20: =IF(phc_8[[#This Row],[Register No.]]="","",C20&"-"&D20&"-"&"BHA-PHC-"&phc_8[[#This Row],[Register No.]]) -> Shining Star-Mobile Clinic-BHA-PHC-18 | N20: New | O20: Daw Tin Tin Mu | P20: 62 | S20: =IF(AND(ISBLANK(P20),ISBLANK(Q20),ISBLANK(R20))," ", IF(OR(P20<5,AND(P20=" ",Q20<>" ",R20<>" ")),"<5 yrs", IF(AND(P20>=5,P20<=14),"5 - 14 yrs", IF(AND(P20>=15,P20<=18),"15 - 18 yrs", IF(AND(P20>=19,P20<=49),"19 - 49 yrs","50 yrs +"))))) -> 50 yrs + | T20: Female | U20: Myit Too | V20: U Bo | W20: HT/DM | X20: DM | Y20: =INDEX(info!$Y$2:$Y$192,MATCH(phc_8[[#This Row],[Sub_Category]],info!$X$2:$X$192,0)) -> Chronic medical disease | Z20: {=INDEX(info!$AA$2:$AA$192,MATCH(PHC!$X20&PHC!$Y20,info!$X$2:$X$192&info!$Y$2:$Y$192,0))} -> Non-communicable disease | AA20: Amlo5, Gliclacide, Ato10, Aspiet, Metformin, Allopurinol | AB20: No | AC20: No | AD20: No | AE20: No | AK20: No | AM20: =IF(AF20="","","Q"&INT((MONTH(AF20)-1)/3)+1&YEAR(AF20)&#REF!&T20) | AN20: =IF(K20="","","Q"&INT((MONTH(K20)-1)/3)+1&YEAR(K20)&#REF!) -> #REF!
A21: 19 | B21: BHA | C21: Shining Star | D21: Mobile Clinic | E21: Mandalay | F21: Amarapura | H21: Myit Too | I21: Village | K21: 46037 | L21: 19 | M21: =IF(phc_8[[#This Row],[Register No.]]="","",C21&"-"&D21&"-"&"BHA-PHC-"&phc_8[[#This Row],[Register No.]]) -> Shining Star-Mobile Clinic-BHA-PHC-19 | N21: New | O21: Daw Myint Moh San | P21: 51 | S21: =IF(AND(ISBLANK(P21),ISBLANK(Q21),ISBLANK(R21))," ", IF(OR(P21<5,AND(P21=" ",Q21<>" ",R21<>" ")),"<5 yrs", IF(AND(P21>=5,P21<=14),"5 - 14 yrs", IF(AND(P21>=15,P21<=18),"15 - 18 yrs", IF(AND(P21>=19,P21<=49),"19 - 49 yrs","50 yrs +"))))) -> 50 yrs + | T21: Female | U21: Myit Too | V21: U Kan | W21: Muscle Pain | X21: Muscle Pain | Y21: =INDEX(info!$Y$2:$Y$192,MATCH(phc_8[[#This Row],[Sub_Category]],info!$X$2:$X$192,0)) -> Other (non-communicable) | Z21: {=INDEX(info!$AA$2:$AA$192,MATCH(PHC!$X21&PHC!$Y21,info!$X$2:$X$192&info!$Y$2:$Y$192,0))} -> Other | AA21: Cefixime, Dextro, Vit C, Betex | AB21: No | AC21: No | AD21: No | AE21: No | AK21: No | AM21: =IF(AF21="","","Q"&INT((MONTH(AF21)-1)/3)+1&YEAR(AF21)&#REF!&T21) | AN21: =IF(K21="","","Q"&INT((MONTH(K21)-1)/3)+1&YEAR(K21)&#REF!) -> #REF!
A22: 20 | B22: BHA | C22: Shining Star | D22: Mobile Clinic | E22: Mandalay | F22: Amarapura | H22: Myit Too | I22: Village | K22: 46037 | L22: 20 | M22: =IF(phc_8[[#This Row],[Register No.]]="","",C22&"-"&D22&"-"&"BHA-PHC-"&phc_8[[#This Row],[Register No.]]) -> Shining Star-Mobile Clinic-BHA-PHC-20 | N22: New | O22: Daw Yee Myint | P22: 61 | S22: =IF(AND(ISBLANK(P22),ISBLANK(Q22),ISBLANK(R22))," ", IF(OR(P22<5,AND(P22=" ",Q22<>" ",R22<>" ")),"<5 yrs", IF(AND(P22>=5,P22<=14),"5 - 14 yrs", IF(AND(P22>=15,P22<=18),"15 - 18 yrs", IF(AND(P22>=19,P22<=49),"19 - 49 yrs","50 yrs +"))))) -> 50 yrs + | T22: Female | U22: Myit Too | V22: U Nyo | W22: DM | X22: DM | Y22: =INDEX(info!$Y$2:$Y$192,MATCH(phc_8[[#This Row],[Sub_Category]],info!$X$2:$X$192,0)) -> Chronic medical disease | Z22: {=INDEX(info!$AA$2:$AA$192,MATCH(PHC!$X22&PHC!$Y22,info!$X$2:$X$192&info!$Y$2:$Y$192,0))} -> Non-communicable disease | AA22: Amlo5, zinc, Betex | AB22: No | AC22: No | AD22: No | AE22: No | AK22: No | AM22: =IF(AF22="","","Q"&INT((MONTH(AF22)-1)/3)+1&YEAR(AF22)&#REF!&T22) | AN22: =IF(K22="","","Q"&INT((MONTH(K22)-1)/3)+1&YEAR(K22)&#REF!) -> #REF!
... A54: 52 | B54: BHA | C54: Shining Star | D54: Mobile Clinic | E54: Mandalay | F54: Amarapura | H54: Myit Too | I54: Village | K54: 46037 | L54: 52 | M54: =IF(phc_8[[#This Row],[Register No.]]="","",C54&"-"&D54&"-"&"BHA-PHC-"&phc_8[[#This Row],[Register No.]]) -> Shining Star-Mobile Clinic-BHA-PHC-52 | N54: New | O54: Daw Kay Thwel Soe | P54: 52 | S54: =IF(AND(ISBLANK(P54),ISBLANK(Q54),ISBLANK(R54))," ", IF(OR(P54<5,AND(P54=" ",Q54<>" ",R54<>" ")),"<5 yrs", IF(AND(P54>=5,P54<=14),"5 - 14 yrs", IF(AND(P54>=15,P54<=18),"15 - 18 yrs", IF(AND(P54>=19,P54<=49),"19 - 49 yrs","50 yrs +"))))) -> 50 yrs + | T54: Female | U54: Myit Too | V54: U Than Ko | W54: Back Pain | X54: Muscle Pain | Y54: =INDEX(info!$Y$2:$Y$192,MATCH(phc_8[[#This Row],[Sub_Category]],info!$X$2:$X$192,0)) -> Other (non-communicable) | Z54: {=INDEX(info!$AA$2:$AA$192,MATCH(PHC!$X54&PHC!$Y54,info!$X$2:$X$192&info!$Y$2:$Y$192,0))} -> Other | AA54: IV B12, Ca+, MV, Gabapentin | AB54: No | AC54: No | AD54: No | AE54: No | AK54: No | AM54: =IF(AF54="","","Q"&INT((MONTH(AF54)-1)/3)+1&YEAR(AF54)&#REF!&T54) | AN54: =IF(K54="","","Q"&INT((MONTH(K54)-1)/3)+1&YEAR(K54)&#REF!) -> #REF!
A55: 53 | B55: BHA | C55: Shining Star | D55: Mobile Clinic | E55: Mandalay | F55: Amarapura | H55: Myit Too | I55: Village | K55: 46037 | L55: 53 | M55: =IF(phc_8[[#This Row],[Register No.]]="","",C55&"-"&D55&"-"&"BHA-PHC-"&phc_8[[#This Row],[Register No.]]) -> Shining Star-Mobile Clinic-BHA-PHC-53 | N55: New | O55: Ma Tin Moe Aung | P55: 30 | S55: =IF(AND(ISBLANK(P55),ISBLANK(Q55),ISBLANK(R55))," ", IF(OR(P55<5,AND(P55=" ",Q55<>" ",R55<>" ")),"<5 yrs", IF(AND(P55>=5,P55<=14),"5 - 14 yrs", IF(AND(P55>=15,P55<=18),"15 - 18 yrs", IF(AND(P55>=19,P55<=49),"19 - 49 yrs","50 yrs +"))))) -> 19 - 49 yrs | T55: Female | U55: Myit Too | W55: Weakness | X55: Weakness | Y55: =INDEX(info!$Y$2:$Y$192,MATCH(phc_8[[#This Row],[Sub_Category]],info!$X$2:$X$192,0)) -> Other (non-communicable) | Z55: {=INDEX(info!$AA$2:$AA$192,MATCH(PHC!$X55&PHC!$Y55,info!$X$2:$X$192&info!$Y$2:$Y$192,0))} -> Other | AA55: MV, Zinc | AB55: No | AC55: No | AD55: No | AE55: No | AK55: No | AM55: =IF(AF55="","","Q"&INT((MONTH(AF55)-1)/3)+1&YEAR(AF55)&#REF!&T55) | AN55: =IF(K55="","","Q"&INT((MONTH(K55)-1)/3)+1&YEAR(K55)&#REF!) -> #REF!
A56: 54 | B56: BHA | C56: Shining Star | D56: Mobile Clinic | E56: Mandalay | F56: Amarapura | H56: Myit Too | I56: Village | K56: 46037 | L56: 54 | M56: =IF(phc_8[[#This Row],[Register No.]]="","",C56&"-"&D56&"-"&"BHA-PHC-"&phc_8[[#This Row],[Register No.]]) -> Shining Star-Mobile Clinic-BHA-PHC-54 | N56: New | O56: Mg Kyaw Zin Htun | Q56: 8 | S56: =IF(AND(ISBLANK(P56),ISBLANK(Q56),ISBLANK(R56))," ", IF(OR(P56<5,AND(P56=" ",Q56<>" ",R56<>" ")),"<5 yrs", IF(AND(P56>=5,P56<=14),"5 - 14 yrs", IF(AND(P56>=15,P56<=18),"15 - 18 yrs", IF(AND(P56>=19,P56<=49),"19 - 49 yrs","50 yrs +"))))) -> <5 yrs | T56: Male | U56: Myit Too | V56: U Kyaw Htoo Aung | W56: Viral | X56: Respiratory viral infection | Y56: =INDEX(info!$Y$2:$Y$192,MATCH(phc_8[[#This Row],[Sub_Category]],info!$X$2:$X$192,0)) -> ARI/RTI | Z56: {=INDEX(info!$AA$2:$AA$192,MATCH(PHC!$X56&PHC!$Y56,info!$X$2:$X$192&info!$Y$2:$Y$192,0))} -> Communicable disease | AA56: Baby Cough, B'ton | AB56: No | AC56: No | AD56: No | AE56: No | AK56: No | AM56: =IF(AF56="","","Q"&INT((MONTH(AF56)-1)/3)+1&YEAR(AF56)&#REF!&T56) | AN56: =IF(K56="","","Q"&INT((MONTH(K56)-1)/3)+1&YEAR(K56)&#REF!) -> #REF!
A57: 55 | B57: BHA | C57: Shining Star | D57: Mobile Clinic | E57: Mandalay | F57: Amarapura | H57: Myit Too | I57: Village | K57: 46037 | L57: 55 | M57: =IF(phc_8[[#This Row],[Register No.]]="","",C57&"-"&D57&"-"&"BHA-PHC-"&phc_8[[#This Row],[Register No.]]) -> Shining Star-Mobile Clinic-BHA-PHC-55 | N57: New | O57: Ma Mya Kyar Phyu | P57: 26 | S57: =IF(AND(ISBLANK(P57),ISBLANK(Q57),ISBLANK(R57))," ", IF(OR(P57<5,AND(P57=" ",Q57<>" ",R57<>" ")),"<5 yrs", IF(AND(P57>=5,P57<=14),"5 - 14 yrs", IF(AND(P57>=15,P57<=18),"15 - 18 yrs", IF(AND(P57>=19,P57<=49),"19 - 49 yrs","50 yrs +"))))) -> 19 - 49 yrs | T57: Female | U57: Myit Too | V57: U Mg Tin | W57: Weakness | X57: Weakness | Y57: =INDEX(info!$Y$2:$Y$192,MATCH(phc_8[[#This Row],[Sub_Category]],info!$X$2:$X$192,0)) -> Other (non-communicable) | Z57: {=INDEX(info!$AA$2:$AA$192,MATCH(PHC!$X57&PHC!$Y57,info!$X$2:$X$192&info!$Y$2:$Y$192,0))} -> Other | AA57: IV B12, MV, Zinc, ORS | AB57: No | AC57: No | AD57: No | AE57: No | AK57: No | AM57: =IF(AF57="","","Q"&INT((MONTH(AF57)-1)/3)+1&YEAR(AF57)&#REF!&T57) | AN57: =IF(K57="","","Q"&INT((MONTH(K57)-1)/3)+1&YEAR(K57)&#REF!) -> #REF!
A58: 56 | B58: BHA | C58: Shining Star | D58: Mobile Clinic | E58: Mandalay | F58: Amarapura | H58: Myit Too | I58: Village | K58: 46037 | L58: 56 | M58: =IF(phc_8[[#This Row],[Register No.]]="","",C58&"-"&D58&"-"&"BHA-PHC-"&phc_8[[#This Row],[Register No.]]) -> Shining Star-Mobile Clinic-BHA-PHC-56 | N58: New | O58: Mg Aung Khant Kyaw | P58: 4 | S58: =IF(AND(ISBLANK(P58),ISBLANK(Q58),ISBLANK(R58))," ", IF(OR(P58<5,AND(P58=" ",Q58<>" ",R58<>" ")),"<5 yrs", IF(AND(P58>=5,P58<=14),"5 - 14 yrs", IF(AND(P58>=15,P58<=18),"15 - 18 yrs", IF(AND(P58>=19,P58<=49),"19 - 49 yrs","50 yrs +"))))) -> <5 yrs | T58: Male | U58: Myit Too | V58: U Kyaw Linn Soe | W58: Skin Problem | X58: Other skin disorders | Y58: =INDEX(info!$Y$2:$Y$192,MATCH(phc_8[[#This Row],[Sub_Category]],info!$X$2:$X$192,0)) -> Skin infection/disease | Z58: {=INDEX(info!$AA$2:$AA$192,MATCH(PHC!$X58&PHC!$Y58,info!$X$2:$X$192&info!$Y$2:$Y$192,0))} -> Non-communicable disease | AA58: Zinc Syrup | AB58: No | AC58: No | AD58: No | AE58: No | AK58: No | AM58: =IF(AF58="","","Q"&INT((MONTH(AF58)-1)/3)+1&YEAR(AF58)&#REF!&T58) | AN58: =IF(K58="","","Q"&INT((MONTH(K58)-1)/3)+1&YEAR(K58)&#REF!) -> #REF!
A59: 57 | B59: BHA | C59: Shining Star | D59: Mobile Clinic | E59: Mandalay | F59: Amarapura | H59: Myit Too | I59: Village | K59: 46037 | L59: 57 | M59: =IF(phc_8[[#This Row],[Register No.]]="","",C59&"-"&D59&"-"&"BHA-PHC-"&phc_8[[#This Row],[Register No.]]) -> Shining Star-Mobile Clinic-BHA-PHC-57 | N59: New | O59: Ma Khin Khin Kyaw | P59: 9 | S59: =IF(AND(ISBLANK(P59),ISBLANK(Q59),ISBLANK(R59))," ", IF(OR(P59<5,AND(P59=" ",Q59<>" ",R59<>" ")),"<5 yrs", IF(AND(P59>=5,P59<=14),"5 - 14 yrs", IF(AND(P59>=15,P59<=18),"15 - 18 yrs", IF(AND(P59>=19,P59<=49),"19 - 49 yrs","50 yrs +"))))) -> 5 - 14 yrs | T59: Female | U59: Myit Too | V59: U Kyaw Linn Soe | W59: Skin Problem | X59: Other skin disorders | Y59: =INDEX(info!$Y$2:$Y$192,MATCH(phc_8[[#This Row],[Sub_Category]],info!$X$2:$X$192,0)) -> Skin infection/disease | Z59: {=INDEX(info!$AA$2:$AA$192,MATCH(PHC!$X59&PHC!$Y59,info!$X$2:$X$192&info!$Y$2:$Y$192,0))} -> Non-communicable disease | AA59: PB vita, Zinc | AB59: No | AC59: No | AD59: No | AE59: No | AK59: No | AM59: =IF(AF59="","","Q"&INT((MONTH(AF59)-1)/3)+1&YEAR(AF59)&#REF!&T59) | AN59: =IF(K59="","","Q"&INT((MONTH(K59)-1)/3)+1&YEAR(K59)&#REF!) -> #REF!
A60: 58 | B60: BHA | C60: Shining Star | D60: Mobile Clinic | E60: Mandalay | F60: Amarapura | H60: Myit Too | I60: Village | K60: 46037 | L60: 58 | M60: =IF(phc_8[[#This Row],[Register No.]]="","",C60&"-"&D60&"-"&"BHA-PHC-"&phc_8[[#This Row],[Register No.]]) -> Shining Star-Mobile Clinic-BHA-PHC-58 | N60: New | O60: Daw Khin Hla | P60: 73 | S60: =IF(AND(ISBLANK(P60),ISBLANK(Q60),ISBLANK(R60))," ", IF(OR(P60<5,AND(P60=" ",Q60<>" ",R60<>" ")),"<5 yrs", IF(AND(P60>=5,P60<=14),"5 - 14 yrs", IF(AND(P60>=15,P60<=18),"15 - 18 yrs", IF(AND(P60>=19,P60<=49),"19 - 49 yrs","50 yrs +"))))) -> 50 yrs + | T60: Female | U60: Myit Too | V60: U Chit | W60: Both Knee Pain | X60: Injuries | Y60: =INDEX(info!$Y$2:$Y$192,MATCH(phc_8[[#This Row],[Sub_Category]],info!$X$2:$X$192,0)) -> Accident/minor sugical and injuries | Z60: {=INDEX(info!$AA$2:$AA$192,MATCH(PHC!$X60&PHC!$Y60,info!$X$2:$X$192&info!$Y$2:$Y$192,0))} -> Injury related | AA60: IV B12, Ibu, Omex, Ca+, MV | AB60: No | AC60: No | AD60: No | AE60: No | AK60: No | AM60: =IF(AF60="","","Q"&INT((MONTH(AF60)-1)/3)+1&YEAR(AF60)&#REF!&T60) | AN60: =IF(K60="","","Q"&INT((MONTH(K60)-1)/3)+1&YEAR(K60)&#REF!) -> #REF!
A61: 59 | B61: BHA | C61: Shining Star | D61: Mobile Clinic | E61: Mandalay | F61: Amarapura | H61: Myit Too | I61: Village | K61: 46037 | L61: 59 | M61: =IF(phc_8[[#This Row],[Register No.]]="","",C61&"-"&D61&"-"&"BHA-PHC-"&phc_8[[#This Row],[Register No.]]) -> Shining Star-Mobile Clinic-BHA-PHC-59 | N61: New | O61: Daw Aye Thaung | P61: 83 | S61: =IF(AND(ISBLANK(P61),ISBLANK(Q61),ISBLANK(R61))," ", IF(OR(P61<5,AND(P61=" ",Q61<>" ",R61<>" ")),"<5 yrs", IF(AND(P61>=5,P61<=14),"5 - 14 yrs", IF(AND(P61>=15,P61<=18),"15 - 18 yrs", IF(AND(P61>=19,P61<=49),"19 - 49 yrs","50 yrs +"))))) -> 50 yrs + | T61: Female | U61: Myit Too | V61: U Mg Ngway | W61: Asthma | X61: Asthma | Y61: =INDEX(info!$Y$2:$Y$192,MATCH(phc_8[[#This Row],[Sub_Category]],info!$X$2:$X$192,0)) -> Asthma | Z61: {=INDEX(info!$AA$2:$AA$192,MATCH(PHC!$X61&PHC!$Y61,info!$X$2:$X$192&info!$Y$2:$Y$192,0))} -> Non-communicable disease | AA61: IV Hydrocortisone, Predinisolone, Dextro, Deriphylline, Cefixime, MV | AB61: No | AC61: No | AD61: No | AE61: No | AK61: No | AM61: =IF(AF61="","","Q"&INT((MONTH(AF61)-1)/3)+1&YEAR(AF61)&#REF!&T61) | AN61: =IF(K61="","","Q"&INT((MONTH(K61)-1)/3)+1&YEAR(K61)&#REF!) -> #REF!
A62: 60 | B62: BHA | C62: Shining Star | D62: Mobile Clinic | E62: Mandalay | F62: Amarapura | H62: Myit Too | I62: Village | K62: 46037 | L62: 60 | M62: =IF(phc_8[[#This Row],[Register No.]]="","",C62&"-"&D62&"-"&"BHA-PHC-"&phc_8[[#This Row],[Register No.]]) -> Shining Star-Mobile Clinic-BHA-PHC-60 | N62: New | O62: Daw Cherry Win | P62: 52 | S62: =IF(AND(ISBLANK(P62),ISBLANK(Q62),ISBLANK(R62))," ", IF(OR(P62<5,AND(P62=" ",Q62<>" ",R62<>" ")),"<5 yrs", IF(AND(P62>=5,P62<=14),"5 - 14 yrs", IF(AND(P62>=15,P62<=18),"15 - 18 yrs", IF(AND(P62>=19,P62<=49),"19 - 49 yrs","50 yrs +"))))) -> 50 yrs + | T62: Female | U62: Myit Too | V62: U Myint Kyi | W62: Weakness | X62: Weakness | Y62: =INDEX(info!$Y$2:$Y$192,MATCH(phc_8[[#This Row],[Sub_Category]],info!$X$2:$X$192,0)) -> Other (non-communicable) | Z62: {=INDEX(info!$AA$2:$AA$192,MATCH(PHC!$X62&PHC!$Y62,info!$X$2:$X$192&info!$Y$2:$Y$192,0))} -> Other | AA62: IV 25%+VitC+B12, MV, Para, Cinnarizine | AB62: No | AC62: No | AD62: No | AE62: No | AK62: No | AM62: =IF(AF62="","","Q"&INT((MONTH(AF62)-1)/3)+1&YEAR(AF62)&#REF!&T62) | AN62: =IF(K62="","","Q"&INT((MONTH(K62)-1)/3)+1&YEAR(K62)&#REF!) -> #REF!
A63: 61 | B63: BHA | C63: Shining Star | D63: Mobile Clinic | E63: Mandalay | F63: Amarapura | H63: Myit Too | I63: Village | K63: 46037 | L63: 61 | M63: =IF(phc_8[[#This Row],[Register No.]]="","",C63&"-"&D63&"-"&"BHA-PHC-"&phc_8[[#This Row],[Register No.]]) -> Shining Star-Mobile Clinic-BHA-PHC-61 | N63: New | O63: Ma Thu Zar Maw | P63: 44 | S63: =IF(AND(ISBLANK(P63),ISBLANK(Q63),ISBLANK(R63))," ", IF(OR(P63<5,AND(P63=" ",Q63<>" ",R63<>" ")),"<5 yrs", IF(AND(P63>=5,P63<=14),"5 - 14 yrs", IF(AND(P63>=15,P63<=18),"15 - 18 yrs", IF(AND(P63>=19,P63<=49),"19 - 49 yrs","50 yrs +"))))) -> 19 - 49 yrs | T63: Female | U63: Myit Too | V63: U Than Ko | W63: Weakness | X63: Weakness | Y63: =INDEX(info!$Y$2:$Y$192,MATCH(phc_8[[#This Row],[Sub_Category]],info!$X$2:$X$192,0)) -> Other (non-communicable) | Z63: {=INDEX(info!$AA$2:$AA$192,MATCH(PHC!$X63&PHC!$Y63,info!$X$2:$X$192&info!$Y$2:$Y$192,0))} -> Other | AA63: MV, Dextro, Cinnarizine, Cetrizine | AB63: No | AC63: No | AD63: No | AE63: No | AK63: No | AM63: =IF(AF63="","","Q"&INT((MONTH(AF63)-1)/3)+1&YEAR(AF63)&#REF!&T63) | AN63: =IF(K63="","","Q"&INT((MONTH(K63)-1)/3)+1&YEAR(K63)&#REF!) -> #REF!
A64: 62 | B64: BHA | C64: Shining Star | D64: Mobile Clinic | E64: Mandalay | F64: Amarapura | H64: Myit Too | I64: Village | K64: 46037 | L64: 62 | M64: =IF(phc_8[[#This Row],[Register No.]]="","",C64&"-"&D64&"-"&"BHA-PHC-"&phc_8[[#This Row],[Register No.]]) -> Shining Star-Mobile Clinic-BHA-PHC-62 | N64: New | O64: Daw Nway Oo | P64: 57 | S64: =IF(AND(ISBLANK(P64),ISBLANK(Q64),ISBLANK(R64))," ", IF(OR(P64<5,AND(P64=" ",Q64<>" ",R64<>" ")),"<5 yrs", IF(AND(P64>=5,P64<=14),"5 - 14 yrs", IF(AND(P64>=15,P64<=18),"15 - 18 yrs", IF(AND(P64>=19,P64<=49),"19 - 49 yrs","50 yrs +"))))) -> 50 yrs + | T64: Female | U64: Myit Too | V64: U Htway Tin | W64: Weakness | X64: Weakness | Y64: =INDEX(info!$Y$2:$Y$192,MATCH(phc_8[[#This Row],[Sub_Category]],info!$X$2:$X$192,0)) -> Other (non-communicable) | Z64: {=INDEX(info!$AA$2:$AA$192,MATCH(PHC!$X64&PHC!$Y64,info!$X$2:$X$192&info!$Y$2:$Y$192,0))} -> Other | AA64: IV B12, Cinnarizine, Betex, MV | AB64: No | AC64: No | AD64: No | AE64: No | AK64: No | AM64: =IF(AF64="","","Q"&INT((MONTH(AF64)-1)/3)+1&YEAR(AF64)&#REF!&T64) | AN64: =IF(K64="","","Q"&INT((MONTH(K64)-1)/3)+1&YEAR(K64)&#REF!) -> #REF!
A65: 63 | B65: BHA | C65: Shining Star | D65: Mobile Clinic | E65: Mandalay | F65: Amarapura | H65: Myit Too | I65: Village | K65: 46037 | L65: 63 | M65: =IF(phc_8[[#This Row],[Register No.]]="","",C65&"-"&D65&"-"&"BHA-PHC-"&phc_8[[#This Row],[Register No.]]) -> Shining Star-Mobile Clinic-BHA-PHC-63 | N65: New | O65: Ma Phue Pyae Thazin | P65: 6 | S65: =IF(AND(ISBLANK(P65),ISBLANK(Q65),ISBLANK(R65))," ", IF(OR(P65<5,AND(P65=" ",Q65<>" ",R65<>" ")),"<5 yrs", IF(AND(P65>=5,P65<=14),"5 - 14 yrs", IF(AND(P65>=15,P65<=18),"15 - 18 yrs", IF(AND(P65>=19,P65<=49),"19 - 49 yrs","50 yrs +"))))) -> 5 - 14 yrs | T65: Female | U65: Myit Too | V65: U Nay Win Htun | W65: Viral | X65: Respiratory viral infection | Y65: =INDEX(info!$Y$2:$Y$192,MATCH(phc_8[[#This Row],[Sub_Category]],info!$X$2:$X$192,0)) -> ARI/RTI | Z65: {=INDEX(info!$AA$2:$AA$192,MATCH(PHC!$X65&PHC!$Y65,info!$X$2:$X$192&info!$Y$2:$Y$192,0))} -> Communicable disease | AA65: PB Vita | AB65: No | AC65: No | AD65: No | AE65: No | AK65: No | AM65: =IF(AF65="","","Q"&INT((MONTH(AF65)-1)/3)+1&YEAR(AF65)&#REF!&T65) | AN65: =IF(K65="","","Q"&INT((MONTH(K65)-1)/3)+1&YEAR(K65)&#REF!) -> #REF!
A66: 64 | B66: BHA | C66: Shining Star | D66: Mobile Clinic | E66: Mandalay | F66: Amarapura | H66: Myit Too | I66: Village | K66: 46037 | L66: 64 | M66: =IF(phc_8[[#This Row],[Register No.]]="","",C66&"-"&D66&"-"&"BHA-PHC-"&phc_8[[#This Row],[Register No.]]) -> Shining Star-Mobile Clinic-BHA-PHC-64 | N66: New | O66: Daw Myint Myint Moe | P66: 49 | S66: =IF(AND(ISBLANK(P66),ISBLANK(Q66),ISBLANK(R66))," ", IF(OR(P66<5,AND(P66=" ",Q66<>" ",R66<>" ")),"<5 yrs", IF(AND(P66>=5,P66<=14),"5 - 14 yrs", IF(AND(P66>=15,P66<=18),"15 - 18 yrs", IF(AND(P66>=19,P66<=49),"19 - 49 yrs","50 yrs +"))))) -> 19 - 49 yrs | T66: Female | U66: Myit Too | V66: U Kyaw Swe | W66: HT/DM | X66: DM | Y66: =INDEX(info!$Y$2:$Y$192,MATCH(phc_8[[#This Row],[Sub_Category]],info!$X$2:$X$192,0)) -> Chronic medical disease | Z66: {=INDEX(info!$AA$2:$AA$192,MATCH(PHC!$X66&PHC!$Y66,info!$X$2:$X$192&info!$Y$2:$Y$192,0))} -> Non-communicable disease | AA66: Amlo5, Metformin, Betex, Ato10 | AB66: No | AC66: No | AD66: No | AE66: No | AK66: No | AM66: =IF(AF66="","","Q"&INT((MONTH(AF66)-1)/3)+1&YEAR(AF66)&#REF!&T66) | AN66: =IF(K66="","","Q"&INT((MONTH(K66)-1)/3)+1&YEAR(K66)&#REF!) -> #REF!
A67: 65 | B67: BHA | C67: Shining Star | D67: Mobile Clinic | E67: Mandalay | F67: Amarapura | H67: Myit Too | I67: Village | K67: 46037 | L67: 65 | M67: =IF(phc_8[[#This Row],[Register No.]]="","",C67&"-"&D67&"-"&"BHA-PHC-"&phc_8[[#This Row],[Register No.]]) -> Shining Star-Mobile Clinic-BHA-PHC-65 | N67: New | O67: Ma Linn Latt Nyein | P67: 28 | S67: =IF(AND(ISBLANK(P67),ISBLANK(Q67),ISBLANK(R67))," ", IF(OR(P67<5,AND(P67=" ",Q67<>" ",R67<>" ")),"<5 yrs", IF(AND(P67>=5,P67<=14),"5 - 14 yrs", IF(AND(P67>=15,P67<=18),"15 - 18 yrs", IF(AND(P67>=19,P67<=49),"19 - 49 yrs","50 yrs +"))))) -> 19 - 49 yrs | T67: Female | U67: Myit Too | V67: U Mg Tin | W67: Weakness | X67: Weakness | Y67: =INDEX(info!$Y$2:$Y$192,MATCH(phc_8[[#This Row],[Sub_Category]],info!$X$2:$X$192,0)) -> Other (non-communicable) | Z67: {=INDEX(info!$AA$2:$AA$192,MATCH(PHC!$X67&PHC!$Y67,info!$X$2:$X$192&info!$Y$2:$Y$192,0))} -> Other | AA67: MV | AB67: No | AC67: No | AD67: No | AE67: No | AK67: No | AM67: =IF(AF67="","","Q"&INT((MONTH(AF67)-1)/3)+1&YEAR(AF67)&#REF!&T67) | AN67: =IF(K67="","","Q"&INT((MONTH(K67)-1)/3)+1&YEAR(K67)&#REF!) -> #REF!
A68: 66 | B68: BHA | C68: Shining Star | D68: Mobile Clinic | E68: Mandalay | F68: Amarapura | H68: Myit Too | I68: Village | K68: 46037 | L68: 66 | M68: =IF(phc_8[[#This Row],[Register No.]]="","",C68&"-"&D68&"-"&"BHA-PHC-"&phc_8[[#This Row],[Register No.]]) -> Shining Star-Mobile Clinic-BHA-PHC-66 | N68: New | O68: Mg Htoo Wai Htun | P68: 2 | S68: =IF(AND(ISBLANK(P68),ISBLANK(Q68),ISBLANK(R68))," ", IF(OR(P68<5,AND(P68=" ",Q68<>" ",R68<>" ")),"<5 yrs", IF(AND(P68>=5,P68<=14),"5 - 14 yrs", IF(AND(P68>=15,P68<=18),"15 - 18 yrs", IF(AND(P68>=19,P68<=49),"19 - 49 yrs","50 yrs +"))))) -> <5 yrs | T68: Male | U68: Myit Too | V68: U Thae Ko | W68: Viral | X68: Respiratory viral infection | Y68: =INDEX(info!$Y$2:$Y$192,MATCH(phc_8[[#This Row],[Sub_Category]],info!$X$2:$X$192,0)) -> ARI/RTI | Z68: {=INDEX(info!$AA$2:$AA$192,MATCH(PHC!$X68&PHC!$Y68,info!$X$2:$X$192&info!$Y$2:$Y$192,0))} -> Communicable disease | AA68: Zinc Syrup | AB68: No | AC68: No | AD68: No | AE68: No | AK68: No | AM68: =IF(AF68="","","Q"&INT((MONTH(AF68)-1)/3)+1&YEAR(AF68)&#REF!&T68) | AN68: =IF(K68="","","Q"&INT((MONTH(K68)-1)/3)+1&YEAR(K68)&#REF!) -> #REF!
... A74: 72 | B74: BHA | C74: Shining Star | D74: Mobile Clinic | E74: Mandalay | F74: Amarapura | H74: Myit Too | I74: Village | K74: 46037 | L74: 72 | M74: =IF(phc_8[[#This Row],[Register No.]]="","",C74&"-"&D74&"-"&"BHA-PHC-"&phc_8[[#This Row],[Register No.]]) -> Shining Star-Mobile Clinic-BHA-PHC-72 | N74: New | O74: Daw Lwin Mar Oo | P74: 58 | S74: =IF(AND(ISBLANK(P74),ISBLANK(Q74),ISBLANK(R74))," ", IF(OR(P74<5,AND(P74=" ",Q74<>" ",R74<>" ")),"<5 yrs", IF(AND(P74>=5,P74<=14),"5 - 14 yrs", IF(AND(P74>=15,P74<=18),"15 - 18 yrs", IF(AND(P74>=19,P74<=49),"19 - 49 yrs","50 yrs +"))))) -> 50 yrs + | T74: Female | U74: Myit Too | V74: U Htay | W74: HT | X74: Hypertension | Y74: =INDEX(info!$Y$2:$Y$192,MATCH(phc_8[[#This Row],[Sub_Category]],info!$X$2:$X$192,0)) -> Chronic medical disease | Z74: {=INDEX(info!$AA$2:$AA$192,MATCH(PHC!$X74&PHC!$Y74,info!$X$2:$X$192&info!$Y$2:$Y$192,0))} -> Non-communicable disease | AA74: Losar, Aldactone, Omex, Atenolol, Siloxogene | AB74: No | AC74: No | AD74: No | AE74: No | AK74: No | AM74: =IF(AF74="","","Q"&INT((MONTH(AF74)-1)/3)+1&YEAR(AF74)&#REF!&T74) | AN74: =IF(K74="","","Q"&INT((MONTH(K74)-1)/3)+1&YEAR(K74)&#REF!) -> #REF!
A75: 73 | B75: BHA | C75: Shining Star | D75: Mobile Clinic | E75: Mandalay | F75: Amarapura | H75: Myit Too | I75: Village | K75: 46037 | L75: 73 | M75: =IF(phc_8[[#This Row],[Register No.]]="","",C75&"-"&D75&"-"&"BHA-PHC-"&phc_8[[#This Row],[Register No.]]) -> Shining Star-Mobile Clinic-BHA-PHC-73 | N75: New | O75: Daw Naing Naing Latt | P75: 41 | S75: =IF(AND(ISBLANK(P75),ISBLANK(Q75),ISBLANK(R75))," ", IF(OR(P75<5,AND(P75=" ",Q75<>" ",R75<>" ")),"<5 yrs", IF(AND(P75>=5,P75<=14),"5 - 14 yrs", IF(AND(P75>=15,P75<=18),"15 - 18 yrs", IF(AND(P75>=19,P75<=49),"19 - 49 yrs","50 yrs +"))))) -> 19 - 49 yrs | T75: Female | U75: Myit Too | V75: U Min Naing | W75: Cervical Spondylosis | Y75: =INDEX(info!$Y$2:$Y$192,MATCH(phc_8[[#This Row],[Sub_Category]],info!$X$2:$X$192,0)) -> #N/A | Z75: {=INDEX(info!$AA$2:$AA$192,MATCH(PHC!$X75&PHC!$Y75,info!$X$2:$X$192&info!$Y$2:$Y$192,0))} -> #N/A | AA75: IV B12, Para, Cinnarizine, Betex | AB75: No | AC75: No | AD75: No | AE75: No | AK75: No | AM75: =IF(AF75="","","Q"&INT((MONTH(AF75)-1)/3)+1&YEAR(AF75)&#REF!&T75) | AN75: =IF(K75="","","Q"&INT((MONTH(K75)-1)/3)+1&YEAR(K75)&#REF!) -> #REF!
A76: 74 | B76: BHA | C76: Shining Star | D76: Mobile Clinic | E76: Mandalay | F76: Amarapura | H76: Myit Too | I76: Village | K76: 46037 | L76: 74 | M76: =IF(phc_8[[#This Row],[Register No.]]="","",C76&"-"&D76&"-"&"BHA-PHC-"&phc_8[[#This Row],[Register No.]]) -> Shining Star-Mobile Clinic-BHA-PHC-74 | N76: New | O76: Daw Pyone | P76: 56 | S76: =IF(AND(ISBLANK(P76),ISBLANK(Q76),ISBLANK(R76))," ", IF(OR(P76<5,AND(P76=" ",Q76<>" ",R76<>" ")),"<5 yrs", IF(AND(P76>=5,P76<=14),"5 - 14 yrs", IF(AND(P76>=15,P76<=18),"15 - 18 yrs", IF(AND(P76>=19,P76<=49),"19 - 49 yrs","50 yrs +"))))) -> 50 yrs + | T76: Female | U76: Myit Too | V76: U Kan Thar | W76: HT | X76: Hypertension | Y76: =INDEX(info!$Y$2:$Y$192,MATCH(phc_8[[#This Row],[Sub_Category]],info!$X$2:$X$192,0)) -> Chronic medical disease | Z76: {=INDEX(info!$AA$2:$AA$192,MATCH(PHC!$X76&PHC!$Y76,info!$X$2:$X$192&info!$Y$2:$Y$192,0))} -> Non-communicable disease | AA76: IM Diclo, MV, Para, Amlo5, Zinc | AB76: No | AC76: No | AD76: No | AE76: No | AK76: No | AM76: =IF(AF76="","","Q"&INT((MONTH(AF76)-1)/3)+1&YEAR(AF76)&#REF!&T76) | AN76: =IF(K76="","","Q"&INT((MONTH(K76)-1)/3)+1&YEAR(K76)&#REF!) -> #REF!
...

Sheet MCH
A1: MCH Database | AH1: Note: Please fill the result If only RI done | AK1: ANC1 | AP1: ANC2 | AU1: ANC3 | AZ1: ANC4 | BG1: Kits distribution | BK1: Delivery Information | BV1: PNC1 | BW1: PNC2
